Workbook

Sheet Datasheet
D1: Quality (1=not achieved, 2=major deficits, 3=minor deficits, 4=best) | S1: Correctness (1=incorrect, 2=major issues, 3=minor issues, 4=correct)
B2: Mission requirement (generated by the LLM) | C2: Number of Tries | D2: Comb. avg. quality rating | E2: Prompt Engineer | L2: Evaluator | S2: Avg correctness rating | T2: Prompt Engineer | V2: Evaluator
A3: BT ID | E3: Avg. quality rating | F3: Atomicity | G3: Ambiguity | H3: Completeness | I3: Usability | J3: Consistency | K3: Comment | L3: Avg. quality rating | M3: Atomicity | N3: Ambiguity | O3: Completeness | P3: Usability | Q3: Consistency | R3: Comment | T3: Rating | U3: Comment | V3: Rating | W3: Comment | X3: Prompts
A4: Cycle 1
A5: entry_6 | B5: https://github.com/isselab/2025-models-prompt-engineering-results/blob/main/experiment_samples/cycle_1/mrq_entry_6.txt | C5: 5 | D5: =AVERAGE(E5, L5) -> 2.4 | E5: =AVERAGE(F5, G5, H5, I5, J5) -> 2 | F5: 2 | G5: 2 | H5: 2 | I5: 1 | J5: 3 | K5: Misinterpreted code references. The LLM also included unecessary additional information (Behavioral Flow Reference Mapping) presented in an undesired format. Readability was bad | L5: =AVERAGE(M5, N5, O5, P5, Q5) -> 2.8 | M5: 2 | N5: 3 | O5: 4 | P5: 1 | Q5: 4 | R5: The requirement R11 addresses two atomic functions: “position its arms for grasping” and “navigate to the computed inverse pose”. It is possible to improve the readability of the requirements to enable non-technical users to understand the behavior captured. | S5: =AVERAGE(T5, V5) -> 3.5 | T5: 3 | U5: ask for help may not always be from a human. that detail is not entirely correct | V5: 4 | X5: https://github.com/isselab/2025-models-prompt-engineering-results/blob/main/experiment_samples/cycle_1/prompt_entry_6.txt
A6: entry_64 | B6: https://github.com/isselab/2025-models-prompt-engineering-results/blob/main/experiment_samples/cycle_1/mrq_entry_64.txt | C6: 1 | D6: =AVERAGE(E6, L6) -> 2.7 | E6: =AVERAGE(F6, G6, H6, I6, J6) -> 2.6 | F6: 3 | G6: 3 | H6: 3 | I6: 1 | J6: 3 | K6: code references not consistently applied. readability was bad (usability <) | L6: =AVERAGE(M6, N6, O6, P6, Q6) -> 2.8 | M6: 4 | N6: 3 | O6: 4 | P6: 1 | Q6: 2 | R6: It is possible to improve the readability of the requirements to enable non-technical users to understand the behavior captured. R2 and R8 are redundant. | S6: =AVERAGE(T6, V6) -> 2.5 | T6: 2 | U6: REQ-7 not an accurate requirement. "interesting" cannot be readily inferred from visualizing the BT. REQ-2 and REQ-8 are the same (i.e. redundancy). REQ-13 not so accurate | V6: 3 | W6: R2 and R8 are redundant. | X6: https://github.com/isselab/2025-models-prompt-engineering-results/blob/main/experiment_samples/cycle_1/prompt_entry_64.txt
A7: entry_73 | B7: https://github.com/isselab/2025-models-prompt-engineering-results/blob/main/experiment_samples/cycle_1/mrq_entry_73.txt | C7: 2 | D7: =AVERAGE(E7, L7) -> 2.7 | E7: =AVERAGE(F7, G7, H7, I7, J7) -> 2.8 | F7: 3 | G7: 3 | H7: 4 | I7: 1 | J7: 3 | K7: Note: The BT XML misspells “RetryUntilSuccessful” as “RetryUntilSuccesful,” but LLM uses the intended meaning. Readability was bad | L7: =AVERAGE(M7, N7, O7, P7, Q7) -> 2.6 | M7: 4 | N7: 2 | O7: 2 | P7: 1 | Q7: 4 | R7: In my opinion, some of the inferences may lead to vague requirements (minor incompleteness) due to a lack of information. For example, in R16, how would 'stable orientation' be verified (moderate ambiguity) ? It is possible to improve the readability of the requirements to enable non-technical users to understand the behavior captured. | S7: =AVERAGE(T7, V7) -> 2 | T7: 2 | U7: REQ-3: "reports a SUCCESS condition" is not so accurate. More like a SUCCESS status is returned. A lot of repetirion of concepts. Alot of inferred condition added to action, which may not necessarily be accurate. | V7: 2 | W7: R2, R5, R8 and R11 are difficult to understand. It is necessary to reorganize them. It is possible to improve the readability of the requirements to enable users unambiguously understand the behavior captured | X7: https://github.com/isselab/2025-models-prompt-engineering-results/blob/main/experiment_samples/cycle_1/prompt_entry_73.txt
A8: entry_266 | B8: https://github.com/isselab/2025-models-prompt-engineering-results/blob/main/experiment_samples/cycle_1/mrq_entry_266.txt | C8: 2 | D8: =AVERAGE(E8, L8) -> 2.6 | E8: =AVERAGE(F8, G8, H8, I8, J8) -> 2.4 | F8: 2 | G8: 2 | H8: 3 | I8: 1 | J8: 4 | K8: Code reference misinterpretation. R5 not atomic at all. Bad usability | L8: =AVERAGE(M8, N8, O8, P8, Q8) -> 2.8 | M8: 3 | N8: 3 | O8: 3 | P8: 1 | Q8: 4 | R8: R5 is not atomic. It is not explicitly stated which inputs of one action are outputs of another. In my opinion, this point could be improved if it is a priority. It is possible to improve the readability of the requirements to enable non-technical users to understand the behavior captured. | S8: =AVERAGE(T8, V8) -> 3.5 | T8: 3 | U8: sequence is not explicitly state and input paramaters are mentioned but not defined as input parameters. | V8: 4 | X8: https://github.com/isselab/2025-models-prompt-engineering-results/blob/main/experiment_samples/cycle_1/prompt_entry_266.txt
A9: entry_317 | B9: https://github.com/isselab/2025-models-prompt-engineering-results/blob/main/experiment_samples/cycle_1/mrq_entry_317.txt | C9: 2 | D9: =AVERAGE(E9, L9) -> 2.3 | E9: =AVERAGE(F9, G9, H9, I9, J9) -> 2.2 | F9: 1 | G9: 3 | H9: 3 | I9: 1 | J9: 3 | K9: Inconsistent language: "robot" and "system" mix in wording. Statements can be further decomposed into multiples. There are standalone requiremnts that are not labelled. Poor usabilty | L9: =AVERAGE(M9, N9, O9, P9, Q9) -> 2.4 | M9: 2 | N9: 2 | O9: 4 | P9: 1 | Q9: 3 | R9: Different linguistic patterns are used in the statements. This makes it difficult to understand the requirements in natural language. Some statements may be split into one or more statements. It is possible to improve the readability of the requirements to enable non-technical users to understand the behavior captured. | S9: =AVERAGE(T9, V9) -> 2.5 | T9: 2 | U9: Nuances like nested sequences and roud robin recovery techniques are not explained properly from the staments provided. Vague explanation of actions could lead to misinterpretations | V9: 3 | W9: The statements describe all the nodes of the BT, but the lack of standardization in the language used makes it difficult to validate their correctness. | X9: https://github.com/isselab/2025-models-prompt-engineering-results/blob/main/experiment_samples/cycle_1/prompt_entry_317.txt
A10: entry_375 | B10: https://github.com/isselab/2025-models-prompt-engineering-results/blob/main/experiment_samples/cycle_1/mrq_entry_375.txt | C10: 1 | D10: =AVERAGE(E10, L10) -> 2.5 | E10: =AVERAGE(F10, G10, H10, I10, J10) -> 2.8 | F10: 1 | G10: 4 | H10: 4 | I10: 1 | J10: 4 | K10: one instance of "the system" instead of "the robot". Atomicity and usability is violated | L10: =AVERAGE(M10, N10, O10, P10, Q10) -> 2.2 | M10: 2 | N10: 2 | O10: 3 | P10: 1 | Q10: 3 | R10: R3 is not clear. R2 and R3 are not atomic. The statements interchange the terms robot and system. It is possible to improve the readability of the requirements to enable non-technical users to understand the behavior captured. | S10: =AVERAGE(T10, V10) -> 2.5 | T10: 3 | U10: Not the best accuracy and general presentation is bad so the understandability is affected and this may cause inferences to be made on the behavior exhibited. | V10: 2 | W10: R3 is not clear. The parameters "barout", "baz", and "fooin" are not explicitly defined, which makes them difficult to understand. | X10: https://github.com/isselab/2025-models-prompt-engineering-results/blob/main/experiment_samples/cycle_1/prompt_entry_375.txt
A11: entry_411 | B11: https://github.com/isselab/2025-models-prompt-engineering-results/blob/main/experiment_samples/cycle_1/mrq_entry_411.txt | C11: 1 | D11: =AVERAGE(E11, L11) -> 2.4 | E11: =AVERAGE(F11, G11, H11, I11, J11) -> 2.2 | F11: 1 | G11: 4 | H11: 1 | I11: 1 | J11: 4 | K11: R12, R15, R16 are not atomic. Not usable. Code references misunderstood and it makes the text look clumsy. Usability was poor; a mix of code and natural language | L11: =AVERAGE(M11, N11, O11, P11, Q11) -> 2.6 | M11: 2 | N11: 2 | O11: 4 | P11: 1 | Q11: 4 | R11: Some statements are not atomic, for example, R12. The different formats of the statements make it difficult to interpret the description of the requirements in natural language. I think the lack of standardization in the text can lead to ambiguity. It is possible to improve the readability of the requirements to enable non-technical users to understand the behavior captured. | S11: =AVERAGE(T11, V11) -> 3 | T11: 3 | V11: 3 | W11: The presentation is not organized and is hard to follow; consequently, the described behavior might be misinterpreted | X11: https://github.com/isselab/2025-models-prompt-engineering-results/blob/main/experiment_samples/cycle_1/prompt_entry_411.txt
A12: entry_457 | B12: https://github.com/isselab/2025-models-prompt-engineering-results/blob/main/experiment_samples/cycle_1/mrq_entry_457.txt | C12: 1 | D12: =AVERAGE(E12, L12) -> 2.2 | E12: =AVERAGE(F12, G12, H12, I12, J12) -> 2 | F12: 1 | G12: 2 | H12: 3 | I12: 1 | J12: 3 | K12: R11 AND R12 atomicity issues. Also no code references included. "if impassable" sounds a little contradictory. Poor presentation | L12: =AVERAGE(M12, N12, O12, P12, Q12) -> 2.4 | M12: 2 | N12: 2 | O12: 4 | P12: 1 | Q12: 3 | R12: The wording mixes 'system' and 'vehicle'. Furthermore, requirements like R4, R11, and R12 should be broken down into atomic statements. It is possible to improve the readability of the requirements to enable non-technical users to understand the behavior captured. | S12: =AVERAGE(T12, V12) -> 3 | T12: 3 | V12: 3 | W12: The lack of standardization in the language used makes it difficult to validate their correctness. | X12: https://github.com/isselab/2025-models-prompt-engineering-results/blob/main/experiment_samples/cycle_1/prompt_entry_457.txt
A13: entry_467 | B13: https://github.com/isselab/2025-models-prompt-engineering-results/blob/main/experiment_samples/cycle_1/mrq_entry_467.txt | C13: 1 | D13: =AVERAGE(E13, L13) -> 2.8 | E13: =AVERAGE(F13, G13, H13, I13, J13) -> 3 | F13: 3 | G13: 4 | H13: 3 | I13: 1 | J13: 4 | K13: "the object" instead of the robot. Code references that are not easily understandable. Poor presentation | L13: =AVERAGE(M13, N13, O13, P13, Q13) -> 2.6 | M13: 3 | N13: 2 | O13: 4 | P13: 1 | Q13: 3 | R13: The statements mix the words 'system', 'robot', 'vehicle', and 'manipulator'. It is possible to improve the readability of the requirements. I think some statements are not atomic, for example, R1 and R5. | S13: =AVERAGE(T13, V13) -> 3 | T13: 3 | V13: 3 | W13: The interpreted behavior is correct; however, mixing terminology can lead to misinterpretation (e.g., 'system', 'robot', 'vehicle', and 'manipulator'). | X13: https://github.com/isselab/2025-models-prompt-engineering-results/blob/main/experiment_samples/cycle_1/prompt_entry_467.txt
A14: entry_540 | B14: https://github.com/isselab/2025-models-prompt-engineering-results/blob/main/experiment_samples/cycle_1/mrq_entry_540.txt | C14: 1 | D14: =AVERAGE(E14, L14) -> 2.8 | E14: =AVERAGE(F14, G14, H14, I14, J14) -> 2.8 | F14: 1 | G14: 4 | H14: 4 | I14: 1 | J14: 4 | K14: too much contextual info given. Minor ordering issue. Poorly presented. thus not usable | L14: =AVERAGE(M14, N14, O14, P14, Q14) -> 2.8 | M14: 4 | N14: 2 | O14: 4 | P14: 1 | Q14: 3 | R14: The description can be simplified in terms of technical detail. Redundant info make it long. | S14: =AVERAGE(T14, V14) -> 3 | T14: 2 | U14: key execution nuance missed in interpreting SequencStar | V14: 4 | X14: https://github.com/isselab/2025-models-prompt-engineering-results/blob/main/experiment_samples/cycle_1/prompt_entry_540.txt
A15: Cycle 2
A16: entry_150 | B16: https://github.com/isselab/2025-models-prompt-engineering-results/blob/main/experiment_samples/cycle_2/mrq_entry_150.txt | C16: 4 | D16: =AVERAGE(E16, L16) -> 3.1 | E16: =AVERAGE(F16, G16, H16, I16, J16) -> 3 | F16: 2 | G16: 4 | H16: 4 | I16: 1 | J16: 4 | K16: Some statements are not atomic enough | L16: =AVERAGE(M16, N16, O16, P16, Q16) -> 3.2 | M16: 4 | N16: 3 | O16: 4 | P16: 1 | Q16: 4 | R16: It is possible to improve the readability of the requirements to enable users unambiguously understand the behavior captured | S16: =AVERAGE(T16, V16) -> 4 | T16: 4 | V16: 4 | X16: https://github.com/isselab/2025-models-prompt-engineering-results/blob/main/experiment_samples/cycle_2/prompt_entry_150.txt
A17: entry_220 | B17: https://github.com/isselab/2025-models-prompt-engineering-results/blob/main/experiment_samples/cycle_2/mrq_entry_220.txt | C17: 5 | D17: =AVERAGE(E17, L17) -> 2.8 | E17: =AVERAGE(F17, G17, H17, I17, J17) -> 2.8 | F17: 3 | G17: 3 | H17: 3 | I17: 1 | J17: 4 | K17: Few statements like (Global Fallback Path Handling 6.) are not atomic, some terminilogies are ambiguous without prior context from an overview | L17: =AVERAGE(M17, N17, O17, P17, Q17) -> 2.8 | M17: 3 | N17: 2 | O17: 4 | P17: 1 | Q17: 4 | R17: The presentation is not organized and is hard to follow. It is possible to improve the readability of the requirements to enable users unambiguously understand the behavior captured. Some statements are not atomic (e.g. Lane Keeping State 4.) | S17: =AVERAGE(T17, V17) -> 3 | T17: 3 | U17: Some ambiguities in the sentence formulation may affect correctness slightly | V17: 3 | W17: The description could be improved to make the content clearer. | X17: https://github.com/isselab/2025-models-prompt-engineering-results/blob/main/experiment_samples/cycle_2/prompt_entry_220.txt
A18: entry_272 | B18: https://github.com/isselab/2025-models-prompt-engineering-results/blob/main/experiment_samples/cycle_2/mrq_entry_272.txt | C18: 1 | D18: =AVERAGE(E18, L18) -> 3.1 | E18: =AVERAGE(F18, G18, H18, I18, J18) -> 3 | F18: 3 | G18: 4 | H18: 3 | I18: 1 | J18: 4 | K18: I think maybe MRQ2 can be decomposed into more than one atomic statement. The statement seems complex and loaded. Not very usable in sentence formulation and presentation. Incomplete without an overview | L18: =AVERAGE(M18, N18, O18, P18, Q18) -> 3.2 | M18: 4 | N18: 3 | O18: 4 | P18: 1 | Q18: 4 | R18: It is possible to improve the readability of the requirements to enable users unambiguously understand the behavior captured. | S18: =AVERAGE(T18, V18) -> 4 | T18: 4 | V18: 4 | X18: https://github.com/isselab/2025-models-prompt-engineering-results/blob/main/experiment_samples/cycle_2/prompt_entry_272.txt
A19: entry_418 | B19: https://github.com/isselab/2025-models-prompt-engineering-results/blob/main/experiment_samples/cycle_2/mrq_entry_418.txt | C19: 1 | D19: =AVERAGE(E19, L19) -> 3.1 | E19: =AVERAGE(F19, G19, H19, I19, J19) -> 3.2 | F19: 3 | G19: 4 | H19: 4 | I19: 1 | J19: 4 | K19: Usability still a challenge | L19: =AVERAGE(M19, N19, O19, P19, Q19) -> 3 | M19: 3 | N19: 3 | O19: 4 | P19: 1 | Q19: 4 | R19: Some statements are not atomic (e.g. R22). It is possible to improve the readability of the requirements to enable users unambiguously understand the behavior captured. | S19: =AVERAGE(T19, V19) -> 4 | T19: 4 | V19: 4 | X19: https://github.com/isselab/2025-models-prompt-engineering-results/blob/main/experiment_samples/cycle_2/prompt_entry_418.txt
A20: entry_451 | B20: https://github.com/isselab/2025-models-prompt-engineering-results/blob/main/experiment_samples/cycle_2/mrq_entry_451.txt | C20: 1 | D20: =AVERAGE(E20, L20) -> 2.8 | E20: =AVERAGE(F20, G20, H20, I20, J20) -> 2.6 | F20: 3 | G20: 2 | H20: 4 | I20: 1 | J20: 3 | K20: MRQ3 not atomic. Not very usable; highly technical tone. Remembrance in MRQ13 not round specific. "ends unsuccessfully" is quite ambiguous and contradictory. | L20: =AVERAGE(M20, N20, O20, P20, Q20) -> 3 | M20: 3 | N20: 3 | O20: 4 | P20: 1 | Q20: 4 | R20: It is possible to improve the readability of the requirements to enable users unambiguously understand the behavior captured. Some statements are not atomic (e.g. R3) | S20: =AVERAGE(T20, V20) -> 4 | T20: 4 | V20: 4 | X20: https://github.com/isselab/2025-models-prompt-engineering-results/blob/main/experiment_samples/cycle_2/prompt_entry_451.txt
A21: entry_475 | B21: https://github.com/isselab/2025-models-prompt-engineering-results/blob/main/experiment_samples/cycle_2/mrq_entry_475.txt | C21: 1 | D21: =AVERAGE(E21, L21) -> 2.9 | E21: =AVERAGE(F21, G21, H21, I21, J21) -> 3 | F21: 4 | G21: 4 | H21: 3 | I21: 1 | J21: 3 | K21: Instances of SequenceStar vaguely described. Poor usability. "the Fallback continues to other children (none exist)"---contradiction | L21: =AVERAGE(M21, N21, O21, P21, Q21) -> 2.8 | M21: 4 | N21: 2 | O21: 3 | P21: 1 | Q21: 4 | R21: I didn't understand REQ19 (text "none exist"). Is this a modeling issue?: "19. If the SequenceStar inside the Fallback returns FAILURE, the Fallback continues to other children (none exist), resulting in FAILURE." It is possible to improve the readability of the requirements | S21: =AVERAGE(T21, V21) -> 4 | T21: 4 | V21: 4 | X21: https://github.com/isselab/2025-models-prompt-engineering-results/blob/main/experiment_samples/cycle_2/prompt_entry_475.txt
A22: entry_50 | B22: https://github.com/isselab/2025-models-prompt-engineering-results/blob/main/experiment_samples/cycle_2/mrq_entry_50.txt | C22: 1 | D22: =AVERAGE(E22, L22) -> 3.2 | E22: =AVERAGE(F22, G22, H22, I22, J22) -> 3.2 | F22: 3 | G22: 4 | H22: 4 | I22: 2 | J22: 3 | K22: MRQ 5 &6 display a repeatition in behavior. No general context orvierview of BT behavior; These affect usability drastically. Requirements are quite technical. | L22: =AVERAGE(M22, N22, O22, P22, Q22) -> 3.2 | M22: 4 | N22: 2 | O22: 4 | P22: 2 | Q22: 4 | R22: It is possible to improve the readability of the requirements to enable users unambiguously understand the behavior captured | S22: =AVERAGE(T22, V22) -> 4 | T22: 4 | V22: 4 | X22: https://github.com/isselab/2025-models-prompt-engineering-results/blob/main/experiment_samples/cycle_2/prompt_entry_50.txt
A23: entry_511 | B23: https://github.com/isselab/2025-models-prompt-engineering-results/blob/main/experiment_samples/cycle_2/mrq_entry_511.txt | C23: 1 | D23: =AVERAGE(E23, L23) -> 2.8 | E23: =AVERAGE(F23, G23, H23, I23, J23) -> 2.6 | F23: 3 | G23: 3 | H23: 2 | I23: 2 | J23: 3 | K23: MRQ9 and MRQ17 are both ambiguous. both use the phrase "repeating as necessary" with no maximum iteration count or guard condition. Only mrqs 3, 5, 11, 13, 19, 22 are truly atomic. Mostly consistent aside a couple of consistency issues | L23: =AVERAGE(M23, N23, O23, P23, Q23) -> 3 | M23: 4 | N23: 2 | O23: 4 | P23: 1 | Q23: 4 | R23: Very technical terms are being used. Understandability could be improved for non-technical stakeholders. | S23: =AVERAGE(T23, V23) -> 3.5 | T23: 3 | U23: "repeating as necessary" phrase lacks precision | V23: 4 | X23: https://github.com/isselab/2025-models-prompt-engineering-results/blob/main/experiment_samples/cycle_2/prompt_entry_511.txt
A24: entry_529 | B24: https://github.com/isselab/2025-models-prompt-engineering-results/blob/main/experiment_samples/cycle_2/mrq_entry_529.txt | C24: 1 | D24: =AVERAGE(E24, L24) -> 3 | E24: =AVERAGE(F24, G24, H24, I24, J24) -> 2.8 | F24: 3 | G24: 2 | H24: 3 | I24: 2 | J24: 4 | K24: Apart from MRRQ2 and 7 which are strongly atomic, the rest are moderately atomic. Ambiguity points: "1.0" has not unit. Does "halt" cancel execution or return failure or both? wait doesnt specify if its infinity or timed. MRQ 1 lacks the specific actions that should be executed. | L24: =AVERAGE(M24, N24, O24, P24, Q24) -> 3.2 | M24: 4 | N24: 2 | O24: 4 | P24: 2 | Q24: 4 | R24: It is possible to improve the readability of the requirements to enable users unambiguously understand the behavior captured | S24: =AVERAGE(T24, V24) -> 3.5 | T24: 3 | U24: ambiguity points stated impact correctness score | V24: 4 | X24: https://github.com/isselab/2025-models-prompt-engineering-results/blob/main/experiment_samples/cycle_2/prompt_entry_529.txt
A25: entry_531 | B25: https://github.com/isselab/2025-models-prompt-engineering-results/blob/main/experiment_samples/cycle_2/mrq_entry_531.txt | C25: 1 | D25: =AVERAGE(E25, L25) -> 2.8 | E25: =AVERAGE(F25, G25, H25, I25, J25) -> 2.8 | F25: 3 | G25: 3 | H25: 3 | I25: 2 | J25: 3 | K25: MRQ9 could be split into subs. "is needed" is ambiguous and implicit (how that is determined, not specified). "specified smoother" (MRQ8) is too vague. round-robin is described implicitly. MRQ12 is not usable and describes a behavior that is not found in visualizer; reactivity seems like a full retry | L25: =AVERAGE(M25, N25, O25, P25, Q25) -> 2.8 | M25: 3 | N25: 2 | O25: 4 | P25: 1 | Q25: 4 | R25: Some statements are not atomic, for example, R6. In general, the requirements are not easy to understand; for example, R6, R9, R11, and R14 are particularly technical. My suggestion is to make them less technical. | S25: =AVERAGE(T25, V25) -> 3.5 | T25: 3 | U25: Some of the quality discrepancies detected impact the correctness of the description | V25: 4 | X25: https://github.com/isselab/2025-models-prompt-engineering-results/blob/main/experiment_samples/cycle_2/prompt_entry_531.txt
A26: Cycle 3
A27: entry_58 | B27: https://github.com/isselab/2025-models-prompt-engineering-results/blob/main/experiment_samples/cycle_3/mrq_entry_58.txt | C27: 3 | D27: =AVERAGE(E27, L27) -> 3.2 | E27: =AVERAGE(F27, G27, H27, I27, J27) -> 3.2 | F27: 4 | G27: 3 | H27: 3 | I27: 2 | J27: 4 | K27: A few phrases lack precision:"Wait until go1/go2 completes","Report mission failure". Running status not covered. Req 1 uses the word "sequence" but the actual logic could be percieved as conditional branching i.e. not wrong, but slightly misleadingmisleading. | L27: =AVERAGE(M27, N27, O27, P27, Q27) -> 3.2 | M27: 4 | N27: 3 | O27: 3 | P27: 2 | Q27: 4 | R27: This description does not include details about go1 and go2. This affects completeness. It is possible to improve the readability of the requirements to enable users unambiguously understand the behavior captured | S27: =AVERAGE(T27, V27) -> 4 | T27: 4 | V27: 4 | X27: https://github.com/isselab/2025-models-prompt-engineering-results/blob/main/experiment_samples/cycle_3/prompt_entry_58.txt
A28: entry_77 | B28: https://github.com/isselab/2025-models-prompt-engineering-results/blob/main/experiment_samples/cycle_3/mrq_entry_77.txt | C28: 1 | D28: =AVERAGE(E28, L28) -> 2.8 | E28: =AVERAGE(F28, G28, H28, I28, J28) -> 2.6 | F28: 3 | G28: 3 | H28: 3 | I28: 1 | J28: 3 | K28: MRQ8 can be split into a main and sub. MRQ7: "stop the current sequence and terminate the current cycle";oes terminating a cycle mean the mission proceeds to the next cycle, or halts entirely?Its also not clear what a cycle is. Sounds very technical and presentation makes readability slightly difficult. "Three complete cycles" (MRQ1), "three successfully executed" (MRQ8), and "three successful cycles" (MRQ9) all phrase the same condition differently, introducing subtle interpretive risk. | L28: =AVERAGE(M28, N28, O28, P28, Q28) -> 3 | M28: 3 | N28: 3 | O28: 4 | P28: 1 | Q28: 4 | R28: Very technical terms are being used. Understandability could be improved for non-technical stakeholders. R8 is not atomic. | S28: =AVERAGE(T28, V28) -> 3.5 | T28: 3 | U28: Interpretation risk in 8 and 9 dents the correctness a bit | V28: 4 | X28: https://github.com/isselab/2025-models-prompt-engineering-results/blob/main/experiment_samples/cycle_3/prompt_entry_77.txt
A29: entry_92 | B29: https://github.com/isselab/2025-models-prompt-engineering-results/blob/main/experiment_samples/cycle_3/mrq_entry_92.txt | C29: 1 | D29: =AVERAGE(E29, L29) -> 3 | E29: =AVERAGE(F29, G29, H29, I29, J29) -> 3.2 | F29: 3 | G29: 4 | H29: 3 | I29: 2 | J29: 4 | K29: MRQ29 can be reforemulated into two requirements. No timeout policy for continuously evaluated conditions. Any and all not used consistently. Usability level not strong enough to realsie mission in detail. | L29: =AVERAGE(M29, N29, O29, P29, Q29) -> 2.8 | M29: 3 | N29: 3 | O29: 4 | P29: 1 | Q29: 3 | R29: The output may be simplified. Redundant rules for similar behaviors could be optimized. R29 and R33 are not atomic. It is possible to improve the readability of the requirements to enable users unambiguously understand the behavior captured | S29: =AVERAGE(T29, V29) -> 4 | T29: 4 | V29: 4 | X29: https://github.com/isselab/2025-models-prompt-engineering-results/blob/main/experiment_samples/cycle_3/prompt_entry_92.txt
A30: entry_124 | B30: https://github.com/isselab/2025-models-prompt-engineering-results/blob/main/experiment_samples/cycle_3/mrq_entry_124.txt | C30: 5 | D30: =AVERAGE(E30, L30) -> 2.9 | E30: =AVERAGE(F30, G30, H30, I30, J30) -> 2.8 | F30: 4 | G30: 3 | H30: 2 | I30: 1 | J30: 4 | K30: Repetition is specified in categorised list heading instead of being fused into description. Failure state handing (11-28) not addressed. | L30: =AVERAGE(M30, N30, O30, P30, Q30) -> 3 | M30: 4 | N30: 2 | O30: 4 | P30: 1 | Q30: 4 | R30: Very technical terms are being used. Understandability could be improved for non-technical stakeholders. | S30: =AVERAGE(T30, V30) -> 3.5 | T30: 3 | U30: Some execution states are not mentioned but implied and left to user interpretation so this could be interpreted as incomplete and imprecise | V30: 4 | X30: https://github.com/isselab/2025-models-prompt-engineering-results/blob/main/experiment_samples/cycle_3/prompt_entry_124.txt
A31: entry_155 | B31: https://github.com/isselab/2025-models-prompt-engineering-results/blob/main/experiment_samples/cycle_3/mrq_entry_155.txt | C31: 1 | D31: =AVERAGE(E31, L31) -> 3.4 | E31: =AVERAGE(F31, G31, H31, I31, J31) -> 3.6 | F31: 4 | G31: 3 | H31: 4 | I31: 3 | J31: 4 | K31: The phrase "Wait until the action completes before proceeding" sounds ambiguous | L31: =AVERAGE(M31, N31, O31, P31, Q31) -> 3.2 | M31: 4 | N31: 2 | O31: 4 | P31: 2 | Q31: 4 | R31: Usability can be improved for non-technical stakeholders. I think improving readability can prevent ambiguities. | S31: =AVERAGE(T31, V31) -> 4 | T31: 4 | V31: 4 | X31: https://github.com/isselab/2025-models-prompt-engineering-results/blob/main/experiment_samples/cycle_3/prompt_entry_155.txt
A32: entry_248 | B32: https://github.com/isselab/2025-models-prompt-engineering-results/blob/main/experiment_samples/cycle_3/mrq_entry_248.txt | C32: 5 | D32: =AVERAGE(E32, L32) -> 2.6 | E32: =AVERAGE(F32, G32, H32, I32, J32) -> 2.6 | F32: 3 | G32: 3 | H32: 3 | I32: 1 | J32: 3 | K32: MRQ3,16,21 can be split into multiple sentences. MRQ22: "restart the sequence from the first action"; contradicts SequenceStar behavior. MRQ24 retry count comes off as ambiguous. Is the initial try part of the six retries? | L32: =AVERAGE(M32, N32, O32, P32, Q32) -> 2.6 | M32: 3 | N32: 2 | O32: 4 | P32: 1 | Q32: 3 | R32: "complete the mission" in R25 and "terminate the mission" in R26 seem to be the same thing, but they are not. I think this can lead to ambiguity. R21 can be rearranged in terms of atomicity. This matches BT entry_418 (Cycle 2); however, the description of the requirements has been refined | S32: =AVERAGE(T32, V32) -> 4 | T32: 4 | V32: 4 | X32: https://github.com/isselab/2025-models-prompt-engineering-results/blob/main/experiment_samples/cycle_3/prompt_entry_248.txt
A33: entry_256 | B33: https://github.com/isselab/2025-models-prompt-engineering-results/blob/main/experiment_samples/cycle_3/mrq_entry_256.txt | C33: 1 | D33: =AVERAGE(E33, L33) -> 3.1 | E33: =AVERAGE(F33, G33, H33, I33, J33) -> 3.2 | F33: 4 | G33: 3 | H33: 3 | I33: 2 | J33: 4 | K33: does the mission then proceed to the next cycle, or does it abort all remaining cycles when it terminates sequence execution for that cycle?; A bit of ambiguity there | L33: =AVERAGE(M33, N33, O33, P33, Q33) -> 3 | M33: 3 | N33: 3 | O33: 4 | P33: 1 | Q33: 4 | R33: "inout ports" in R11 can be rewritten as "in/out ports". R11 is not atomic. Very technical terms are being used. Understandability could be improved for non-technical stakeholders. | S33: =AVERAGE(T33, V33) -> 4 | T33: 4 | V33: 4 | X33: https://github.com/isselab/2025-models-prompt-engineering-results/blob/main/experiment_samples/cycle_3/prompt_entry_256.txt
A34: entry_345 | B34: https://github.com/isselab/2025-models-prompt-engineering-results/blob/main/experiment_samples/cycle_3/mrq_entry_345.txt | C34: 1 | D34: =AVERAGE(E34, L34) -> 3.2 | E34: =AVERAGE(F34, G34, H34, I34, J34) -> 3.2 | F34: 4 | G34: 4 | H34: 3 | I34: 1 | J34: 4 | K34: Presentation hampers readability and understandability to a significant extent | L34: =AVERAGE(M34, N34, O34, P34, Q34) -> 3.2 | M34: 4 | N34: 3 | O34: 4 | P34: 1 | Q34: 4 | R34: R2, R5, R8 and R11 are difficult to understand. Maybe we could reorganize them. It is possible to improve the readability of the requirements to enable users unambiguously understand the behavior captured | S34: =AVERAGE(T34, V34) -> 4 | T34: 4 | V34: 4 | X34: https://github.com/isselab/2025-models-prompt-engineering-results/blob/main/experiment_samples/cycle_3/prompt_entry_345.txt
A35: entry_380 | B35: https://github.com/isselab/2025-models-prompt-engineering-results/blob/main/experiment_samples/cycle_3/mrq_entry_380.txt | C35: 1 | D35: =AVERAGE(E35, L35) -> 3.2 | E35: =AVERAGE(F35, G35, H35, I35, J35) -> 3.4 | F35: 4 | G35: 4 | H35: 4 | I35: 2 | J35: 3 | K35: MRQ6 is redundant. MRQ4 and 8 overlap. Seems readable and undestandable. Some strict details are missing but it doesnt hamper reproducibility | L35: =AVERAGE(M35, N35, O35, P35, Q35) -> 3 | M35: 4 | N35: 3 | O35: 2 | P35: 2 | Q35: 4 | R35: The parameters "barout", "baz", and "fooin" were omitted. This BT is very similar to entry_375 (Cycle 1). Usability can be improved for non-technical stakeholders. I think improving readability can prevent ambiguities | S35: =AVERAGE(T35, V35) -> 3 | T35: 3 | U35: Lack of hard parameters makes the correctness a bit fuzzy. | V35: 3 | W35: It describes the expected behavior, but the parameters "barout", "baz", and "fooin" were omitted. | X35: https://github.com/isselab/2025-models-prompt-engineering-results/blob/main/experiment_samples/cycle_3/prompt_entry_380.txt
A36: entry_552 | B36: https://github.com/isselab/2025-models-prompt-engineering-results/blob/main/experiment_samples/cycle_3/mrq_entry_552.txt | C36: 1 | D36: =AVERAGE(E36, L36) -> 3.2 | E36: =AVERAGE(F36, G36, H36, I36, J36) -> 3.4 | F36: 4 | G36: 3 | H36: 4 | I36: 2 | J36: 4 | K36: A few redundant phrases and expressions. Some expressions might not be interpreted precisely | L36: =AVERAGE(M36, N36, O36, P36, Q36) -> 3 | M36: 3 | N36: 3 | O36: 3 | P36: 2 | Q36: 4 | R36: Some requirements are hard to understand without context or more details. For instance, in R6, "mark them as unoccupied' is vague, and 'loci' seems like technical jargon. RQ6 (1-5) can be rearranged in terms of atomicity. | S36: =AVERAGE(T36, V36) -> 4 | T36: 4 | V36: 4 | X36: https://github.com/isselab/2025-models-prompt-engineering-results/blob/main/experiment_samples/cycle_3/prompt_entry_552.txt
A37: Cycle 4
A38: entry_32 | B38: https://github.com/isselab/2025-models-prompt-engineering-results/blob/main/experiment_samples/cycle_4/mrq_entry_32.txt | C38: 4 | D38: =AVERAGE(E38, L38) -> 3.4 | E38: =AVERAGE(F38, G38, H38, I38, J38) -> 3.4 | F38: 3 | G38: 3 | H38: 4 | I38: 4 | J38: 3 | K38: Mission scope kept narrow and concise. Slight tradeoff of atomicity for fluency. More noticable fluency. "before proceeding" could me misinterpreted to mean other actions exist, slighly contadicting the last statement. | L38: =AVERAGE(M38, N38, O38, P38, Q38) -> 3.4 | M38: 4 | N38: 3 | O38: 4 | P38: 3 | Q38: 3 | R38: In the third sentence, "...wait for it to finish before proceeding." contradicts "a single-step mission". There is no other step. | S38: =AVERAGE(T38, V38) -> 4 | T38: 4 | V38: 4 | X38: https://github.com/isselab/2025-models-prompt-engineering-results/blob/main/experiment_samples/cycle_4/prompt_entry_32.txt
A39: entry_41 | B39: https://github.com/isselab/2025-models-prompt-engineering-results/blob/main/experiment_samples/cycle_4/mrq_entry_41.txt | C39: 2 | D39: =AVERAGE(E39, L39) -> 3.5 | E39: =AVERAGE(F39, G39, H39, I39, J39) -> 3.6 | F39: 3 | G39: 4 | H39: 3 | I39: 4 | J39: 4 | K39: Slight tradeoff of atomicity for fluency. Succinctness in understadability make minor aspects of completeness more implicit(i.e failure of sequence actions) | L39: =AVERAGE(M39, N39, O39, P39, Q39) -> 3.4 | M39: 3 | N39: 3 | O39: 4 | P39: 3 | Q39: 4 | R39: The second sentence is a bit ambiguous: "...stop the sequence if any action fails or is still running.". Maybe: "will wait if an action is still running". I suggest splitting it for better clarity. | S39: =AVERAGE(T39, V39) -> 4 | T39: 4 | V39: 4 | X39: https://github.com/isselab/2025-models-prompt-engineering-results/blob/main/experiment_samples/cycle_4/prompt_entry_41.txt
A40: entry_194 | B40: https://github.com/isselab/2025-models-prompt-engineering-results/blob/main/experiment_samples/cycle_4/mrq_entry_194.txt | C40: 2 | D40: =AVERAGE(E40, L40) -> 4 | E40: =AVERAGE(F40, G40, H40, I40, J40) -> 4 | F40: 4 | G40: 4 | H40: 4 | I40: 4 | J40: 4 | L40: =AVERAGE(M40, N40, O40, P40, Q40) -> 4 | M40: 4 | N40: 4 | O40: 4 | P40: 4 | Q40: 4 | S40: =AVERAGE(T40, V40) -> 4 | T40: 4 | V40: 4 | X40: https://github.com/isselab/2025-models-prompt-engineering-results/blob/main/experiment_samples/cycle_4/prompt_entry_194.txt
...

Sheet Plot
C1: Average correctness ratings
A2: Entry | B2: Combined averages of quality ratings | C2: Cycle 1 | D2: Cycle 2 | E2: Cycle 3 | F2: Cycle 4 | G2: Cycle 5
A3: 6 | B3: =Datasheet!D5 -> 2.4 | C3: =Datasheet!S5 -> 3.5
A4: 64 | B4: =Datasheet!D6 -> 2.7 | C4: =Datasheet!S6 -> 2.5
A5: 73 | B5: =Datasheet!D7 -> 2.7 | C5: =Datasheet!S7 -> 2
A6: 266 | B6: =Datasheet!D8 -> 2.6 | C6: =Datasheet!S8 -> 3.5
A7: 317 | B7: =Datasheet!D9 -> 2.3 | C7: =Datasheet!S9 -> 2.5
A8: 375 | B8: =Datasheet!D10 -> 2.5 | C8: =Datasheet!S10 -> 2.5
A9: 411 | B9: =Datasheet!D11 -> 2.4 | C9: =Datasheet!S11 -> 3
A10: 457 | B10: =Datasheet!D12 -> 2.2 | C10: =Datasheet!S12 -> 3
A11: 467 | B11: =Datasheet!D13 -> 2.8 | C11: =Datasheet!S13 -> 3
A12: 540 | B12: =Datasheet!D14 -> 2.8 | C12: =Datasheet!S14 -> 3
A15: 150 | B15: =Datasheet!D16 -> 3.1 | D15: =Datasheet!S16 -> 4
A16: 220 | B16: =Datasheet!D17 -> 2.8 | D16: =Datasheet!S17 -> 3
A17: 272 | B17: =Datasheet!D18 -> 3.1 | D17: =Datasheet!S18 -> 4
A18: 418 | B18: =Datasheet!D19 -> 3.1 | D18: =Datasheet!S19 -> 4
A19: 451 | B19: =Datasheet!D20 -> 2.8 | D19: =Datasheet!S20 -> 4
A20: 475 | B20: =Datasheet!D21 -> 2.9 | D20: =Datasheet!S21 -> 4
A21: 50 | B21: =Datasheet!D22 -> 3.2 | D21: =Datasheet!S22 -> 4
A22: 511 | B22: =Datasheet!D23 -> 2.8 | D22: =Datasheet!S23 -> 3.5
A23: 529 | B23: =Datasheet!D24 -> 3 | D23: =Datasheet!S24 -> 3.5
A24: 531 | B24: =Datasheet!D25 -> 2.8 | D24: =Datasheet!S25 -> 3.5
A27: 58 | B27: =Datasheet!D27 -> 3.2 | E27: =Datasheet!S27 -> 4
A28: 77 | B28: =Datasheet!D28 -> 2.8 | E28: =Datasheet!S28 -> 3.5
A29: 92 | B29: =Datasheet!D29 -> 3 | E29: =Datasheet!S29 -> 4
A30: 124 | B30: =Datasheet!D30 -> 2.9 | E30: =Datasheet!S30 -> 3.5
A31: 155 | B31: =Datasheet!D31 -> 3.4 | E31: =Datasheet!S31 -> 4
A32: 248 | B32: =Datasheet!D32 -> 2.6 | E32: =Datasheet!S32 -> 4
A33: 256 | B33: =Datasheet!D33 -> 3.1 | E33: =Datasheet!S33 -> 4
A34: 345 | B34: =Datasheet!D34 -> 3.2 | E34: =Datasheet!S34 -> 4
A35: 380 | B35: =Datasheet!D35 -> 3.2 | E35: =Datasheet!S35 -> 3
A36: 552 | B36: =Datasheet!D36 -> 3.2 | E36: =Datasheet!S36 -> 4
A39: 32 | B39: =Datasheet!D38 -> 3.4 | F39: =Datasheet!S38 -> 4
A40: 41 | B40: =Datasheet!D39 -> 3.5 | F40: =Datasheet!S39 -> 4
A41: 194 | B41: =Datasheet!D40 -> 4 | F41: =Datasheet!S40 -> 4
A42: 321 | B42: =Datasheet!D41 -> 2.9 | F42: =Datasheet!S41 -> 3.5
A43: 376 | B43: =Datasheet!D42 -> 3.1 | F43: =Datasheet!S42 -> 4
A44: 402 | B44: =Datasheet!D43 -> 3.3 | F44: =Datasheet!S43 -> 4
A45: 435 | B45: =Datasheet!D44 -> 3.1 | F45: =Datasheet!S44 -> 3
A46: 440 | B46: =Datasheet!D45 -> 2.9 | F46: =Datasheet!S45 -> 3.5
...

Sheet Kendall
A1: Cycle | B1: Average quality rating (combined) | C1: Average correctness rating
A2: 1 | B2: =Datasheet!D5 -> 2.4 | C2: =Datasheet!S5 -> 3.5
A3: 1 | B3: =Datasheet!D6 -> 2.7 | C3: =Datasheet!S6 -> 2.5
A4: 1 | B4: =Datasheet!D7 -> 2.7 | C4: =Datasheet!S7 -> 2
A5: 1 | B5: =Datasheet!D8 -> 2.6 | C5: =Datasheet!S8 -> 3.5
A6: 1 | B6: =Datasheet!D9 -> 2.3 | C6: =Datasheet!S9 -> 2.5
A7: 1 | B7: =Datasheet!D10 -> 2.5 | C7: =Datasheet!S10 -> 2.5
A8: 1 | B8: =Datasheet!D11 -> 2.4 | C8: =Datasheet!S11 -> 3
A9: 1 | B9: =Datasheet!D12 -> 2.2 | C9: =Datasheet!S12 -> 3
A10: 1 | B10: =Datasheet!D13 -> 2.8 | C10: =Datasheet!S13 -> 3
A11: 1 | B11: =Datasheet!D14 -> 2.8 | C11: =Datasheet!S14 -> 3
A12: 2 | B12: =Datasheet!D16 -> 3.1 | C12: =Datasheet!S16 -> 4
A13: 2 | B13: =Datasheet!D17 -> 2.8 | C13: =Datasheet!S17 -> 3
A14: 2 | B14: =Datasheet!D18 -> 3.1 | C14: =Datasheet!S18 -> 4
A15: 2 | B15: =Datasheet!D19 -> 3.1 | C15: =Datasheet!S19 -> 4
A16: 2 | B16: =Datasheet!D20 -> 2.8 | C16: =Datasheet!S20 -> 4
A17: 2 | B17: =Datasheet!D21 -> 2.9 | C17: =Datasheet!S21 -> 4
A18: 2 | B18: =Datasheet!D22 -> 3.2 | C18: =Datasheet!S22 -> 4
A19: 2 | B19: =Datasheet!D23 -> 2.8 | C19: =Datasheet!S23 -> 3.5
A20: 2 | B20: =Datasheet!D24 -> 3 | C20: =Datasheet!S24 -> 3.5
A21: 2 | B21: =Datasheet!D25 -> 2.8 | C21: =Datasheet!S25 -> 3.5
A22: 3 | B22: =Datasheet!D27 -> 3.2 | C22: =Datasheet!S27 -> 4
A23: 3 | B23: =Datasheet!D28 -> 2.8 | C23: =Datasheet!S28 -> 3.5
A24: 3 | B24: =Datasheet!D29 -> 3 | C24: =Datasheet!S29 -> 4
A25: 3 | B25: =Datasheet!D30 -> 2.9 | C25: =Datasheet!S30 -> 3.5
A26: 3 | B26: =Datasheet!D31 -> 3.4 | C26: =Datasheet!S31 -> 4
A27: 3 | B27: =Datasheet!D32 -> 2.6 | C27: =Datasheet!S32 -> 4
A28: 3 | B28: =Datasheet!D33 -> 3.1 | C28: =Datasheet!S33 -> 4
A29: 3 | B29: =Datasheet!D34 -> 3.2 | C29: =Datasheet!S34 -> 4
A30: 3 | B30: =Datasheet!D35 -> 3.2 | C30: =Datasheet!S35 -> 3
A31: 3 | B31: =Datasheet!D36 -> 3.2 | C31: =Datasheet!S36 -> 4
A32: 4 | B32: =Datasheet!D38 -> 3.4 | C32: =Datasheet!S38 -> 4
A33: 4 | B33: =Datasheet!D39 -> 3.5 | C33: =Datasheet!S39 -> 4
A34: 4 | B34: =Datasheet!D40 -> 4 | C34: =Datasheet!S40 -> 4
A35: 4 | B35: =Datasheet!D41 -> 2.9 | C35: =Datasheet!S41 -> 3.5
A36: 4 | B36: =Datasheet!D42 -> 3.1 | C36: =Datasheet!S42 -> 4
A37: 4 | B37: =Datasheet!D43 -> 3.3 | C37: =Datasheet!S43 -> 4
A38: 4 | B38: =Datasheet!D44 -> 3.1 | C38: =Datasheet!S44 -> 3
A39: 4 | B39: =Datasheet!D45 -> 2.9 | C39: =Datasheet!S45 -> 3.5
A40: 4 | B40: =Datasheet!D46 -> 3.7 | C40: =Datasheet!S46 -> 3
...

Sheet Quality Distribution
A1: Cycle | B1: Min | C1: Q1 | D1: Median | E1: Q3 | F1: Max
A2: 1 | B2: =MIN(Plot!B3:B12) -> 2.2 | C2: =QUARTILE(Plot!B3:B12,1) -> 2.4 | D2: =MEDIAN(Plot!B3:B12) -> 2.55 | E2: =QUARTILE(Plot!B3:B12,3) -> 2.7 | F2: =MAX(Plot!B3:B12) -> 2.8
A3: 2 | B3: =MIN(Plot!B15:B24) -> 2.8 | C3: =QUARTILE(Plot!B15:B24,1) -> 2.8 | D3: =MEDIAN(Plot!B15:B24) -> 2.95 | E3: =QUARTILE(Plot!B15:B24,3) -> 3.1 | F3: =MAX(Plot!B15:B24) -> 3.2
A4: 3 | B4: =MIN(Plot!B27:B36) -> 2.6 | C4: =QUARTILE(Plot!B27:B36,1) -> 2.925 | D4: =MEDIAN(Plot!B27:B36) -> 3.15 | E4: =QUARTILE(Plot!B27:B36,3) -> 3.2 | F4: =MAX(Plot!B27:B36) -> 3.4
A5: 4 | B5: =MIN(Plot!B39:B48) -> 2.9 | C5: =QUARTILE(Plot!B39:B48,1) -> 3.1 | D5: =MEDIAN(Plot!B39:B48) -> 3.35 | E5: =QUARTILE(Plot!B39:B48,3) -> 3.475 | F5: =MAX(Plot!B39:B48) -> 4
A6: 5 | B6: =MIN(Plot!B51:B60) -> 3.4 | C6: =QUARTILE(Plot!B51:B60,1) -> 3.6 | D6: =MEDIAN(Plot!B51:B60) -> 3.8 | E6: =QUARTILE(Plot!B51:B60,3) -> 3.875 | F6: =MAX(Plot!B51:B60) -> 4

Sheet Correctness Distribution
A1: Cycle | B1: Min | C1: Q1 | D1: Median | E1: Q3 | F1: Max
A2: 1 | B2: =MIN(Datasheet!S5:S14) -> 2 | C2: =QUARTILE(Datasheet!S5:S14,1) -> 2.5 | D2: =MEDIAN(Datasheet!S5:S14) -> 3 | E2: =QUARTILE(Datasheet!S5:S14,3) -> 3 | F2: =MAX(Datasheet!S5:S14) -> 3.5
A3: 2 | B3: =MIN(Datasheet!S16:S25) -> 3 | C3: =QUARTILE(Datasheet!S16:S25,1) -> 3.5 | D3: =MEDIAN(Datasheet!S16:S25) -> 4 | E3: =QUARTILE(Datasheet!S16:S25,3) -> 4 | F3: =MAX(Datasheet!S16:S25) -> 4
A4: 3 | B4: =MIN(Datasheet!S27:S36) -> 3 | C4: =QUARTILE(Datasheet!S27:S36,1) -> 3.625 | D4: =MEDIAN(Datasheet!S27:S36) -> 4 | E4: =QUARTILE(Datasheet!S27:S36,3) -> 4 | F4: =MAX(Datasheet!S27:S36) -> 4
A5: 4 | B5: =MIN(Datasheet!S38:S47) -> 3 | C5: =QUARTILE(Datasheet!S38:S47,1) -> 3.5 | D5: =MEDIAN(Datasheet!S38:S47) -> 4 | E5: =QUARTILE(Datasheet!S38:S47,3) -> 4 | F5: =MAX(Datasheet!S38:S47) -> 4
A6: 5 | B6: =MIN(Datasheet!S49:S58) -> 3.5 | C6: =QUARTILE(Datasheet!S49:S58,1) -> 4 | D6: =MEDIAN(Datasheet!S49:S58) -> 4 | E6: =QUARTILE(Datasheet!S49:S58,3) -> 4 | F6: =MAX(Datasheet!S49:S58) -> 4

Sheet Screened, Extracted and Matched
A1: Screening
A2: Document | B2: Content Summary
A3: ISO/IEC/IEEE 29148:2018 | B3: Distinguishes characteristics of individual requirements and of a set of requirements.
A4: ISO/IEC/IEEE 15288:2015 | B4: Does not define micro‑level requirement statement qualities (like unambiguous or singular etc.) explicitly. However it presents and uses higher‑level notions of requirement and system quality.
A5: ISO/IEC/IEEE 12207:2017 | B5: Similar pattern as 15288 identified. Document is process‑oriented, with quality properties implied rather than named as requirement‑statement attributes.
A6: ISO/IEC 25010 | B6: This is a product‑quality and quality‑in‑use model.
A7: IEEE 1061-1992 | B7: Defines a methodology for metrics over software quality attributes rather than a fixed catalog, but its examples align with classic factors like usability.
A8: INCOSE Guide for Writing Requirements (incl. V3/V4) | B8: Gives a clear set of characteristics for individual requirements and for sets.
A10: Extraction and Matching
A11: Quality | B11: ISO/IEC/IEEE 29148:2018 | C11: ISO/IEC/IEEE 15288:2015 | D11: ISO/IEC/IEEE 12207:2017 | E11: ISO/IEC 25010 | F11: IEEE 1061-1992 | G11: INCOSE Guide for Writing Requirements (incl. V3/V4)
A12: Atomicity | B12: Singular (each requirement states a single capability, characteristic, constraint, or quality factor). | C12: Implicitly supported via requirement traceability/uniqueness and manageable requirement items, but no explicit “atomic” or “singular” characteristic. | D12: Not explicitly defined; implied via manageable software requirements items. | E12: No direct equivalent | F12: Not a defined quality or metric in the taxonomy but it is handled at requirements/specification level. | G12: Singular (each requirement states a single capability/characteristic).
A13: Ambiguity | B13: Unambiguous (requirement can be interpreted in only one way by all intended audiences). | C13: Implicitly discouraged through requirements processes; no explicit “unambiguous” requirement characteristic. | D13: Not explicitly named, however avoiding ambiguous staements is part of good SRS practice aligned with 29148. | E13: No direct attribute matches this. Ambiguity is usually treated in requirements quality, not product quality. | F13: Not explicitly listed but framed as a measurable attributes such as reliability. | G13: Unambiguous / Non‑ambiguous (one and only one interpretation; avoid vague words).
A14: Completeness | B14: Complete (requirements set stands alone and addresses all necessary aspects) | C14: Complete requirement set is implied in verification/validation outcomes and stakeholder requirements definition, but not formalized as a named attribute. | D14: Completeness of software requirements is a goal of the Software Requirements Definition and Verification processes, but not labeled as a formal attribute. | E14: Functional completeness (sub‑characteristic of Functional suitability: all specified functions are provided). | F14: Addressed via functional completeness and “meeting quality requirements” through metrics, but not a standalone named factor. | G14: For individual requirements: Complete (no further amplification needed); for sets: Complete (set sufficiently describes all necessary aspects).
A15: Usability | B15: Not listed as a requirement quality but appears as a requirement type (e.g., “Usability requirements” in SyRS/SRS content). | C15: Appears as a system quality characteristic / non‑functional requirement (e.g., usability requirements in operational quality) | D15: Treated as a software product quality / non-functional requirement category (usability requirements). | E15: Usability (top‑level product quality characteristic with sub‑characteristics such as learnability, operability, user error protection, accessibility). | F15: Usability as a quality factor, with sub‑factors like ease of learning, operability, understandability, communicativeness. | G15: Not a requirement‑statement quality; appears as a type of requirement (usability requirement) aligned with ISO 25010 usability.
A16: Consistency | B16: Consistent (no conflicts inside a requirement set, same terms used consistently). | C16: Requirement consistency is implied in “consistent with stakeholder needs and architecture” but not enumerated as a named requirement attribute. | D16: Implied consistency within and between software requirements and higher‑level requirements, but not named as a standalone attribute. | E16: No explicit “consistency” characteristic. However related concepts appear under Compatibility (interoperability, coexistence) and Usability (consistent UI etc.). | F16: Not a named quality but is implied under correctness or reliability metrics. | G16: Consistent (no conflicts among requirements; homogeneous terminology across the set).
